I'm sorry, but an uncaught exception occurred.

While running game code:
  File "game/script.rpy", line 9, in script call
    call tryscene
  File "game/Chapters/amberchapte.rpy", line 5, in script call
    call charlaamb
  File "game/Chapters/amberchapte.rpy", line 16, in script
    scene Diary xfill True yfill True with flashbulb  # Se asegura que el fondo se muestre correctamente
Exception: Image 'Diary' does not accept attributes 'xfill True yfill True'.

-- Full Traceback ------------------------------------------------------------

Full traceback:
  File "game/script.rpy", line 9, in script call
    call tryscene
  File "game/Chapters/amberchapte.rpy", line 5, in script call
    call charlaamb
  File "game/Chapters/amberchapte.rpy", line 16, in script
    scene Diary xfill True yfill True with flashbulb  # Se asegura que el fondo se muestre correctamente
  File "C:\Users\MercuryMat\Documents\renpy-8.3.4-sdk\renpy\ast.py", line 1251, in execute
    show_imspec(self.imspec, atl=getattr(self, "atl", None))
  File "C:\Users\MercuryMat\Documents\renpy-8.3.4-sdk\renpy\ast.py", line 1080, in show_imspec
    renpy.config.show(name,
  File "C:\Users\MercuryMat\Documents\renpy-8.3.4-sdk\renpy\exports\displayexports.py", line 477, in show
    if not base.find_target() and renpy.config.missing_show:
  File "C:\Users\MercuryMat\Documents\renpy-8.3.4-sdk\renpy\display\image.py", line 421, in find_target
    self.target = target._duplicate(a)
  File "C:\Users\MercuryMat\Documents\renpy-8.3.4-sdk\renpy\display\displayable.py", line 249, in _duplicate
    args.extraneous()
  File "C:\Users\MercuryMat\Documents\renpy-8.3.4-sdk\renpy\display\displayable.py", line 109, in extraneous
    raise Exception("Image '{}' does not accept attributes '{}'.".format(
Exception: Image 'Diary' does not accept attributes 'xfill True yfill True'.

Windows-10-10.0.26100 AMD64
Ren'Py 8.3.4.24120703
 
Mon Feb  3 01:28:58 2025
